Workbook
Name CategoryList: 'August 2026 Archive'!$J$2:INDEX('August 2026 Archive'!$J:$J,COUNTA('August 2026 Archive'!$J:$J))
Name CategoryList: Expenses!$J$2:INDEX(Expenses!$J:$J,COUNTA(Expenses!$J:$J))
Name SubcategoryList: 'August 2026 Archive'!$K$2:INDEX('August 2026 Archive'!$K:$K,COUNTA('August 2026 Archive'!$K:$K))
Name SubcategoryList: Expenses!$K$2:INDEX(Expenses!$K:$K,COUNTA(Expenses!$K:$K))

Sheet Cover
A1: Personal Finance Workbook
A2: Expense tracking plus savings and emergency fund monitoring.
A4: Sheet | B4: Purpose
A5: Expenses | B5: Enter daily expenses and categories.
A6: Dashboard | B6: Expense dashboard with monthly, daily, category, and subcategory summaries.
A7: Savings Tracker | B7: Enter savings and emergency fund contributions or withdrawals.
A8: Savings Dashboard | B8: Track current savings balance, emergency fund target, progress, and trends.
A9: Web App Plan | B9: Blueprint for converting the workbook into a web application.
A10: Web App Mockup | B10: Visual sample design for the personal finance web application.
A11: August 2026 Archive | B11: Historical copy of all August 2026 expense records.
A12: Savings Plan | B12: Balanced 40% savings plan with twice-monthly allocations and fixed-bill breakdown.
A13: Farm Manager Salary | B13: Record provincial farm manager salary and allowance payments.

Sheet Dashboard
A1: Expense Dashboard
A2: Select a month, enter an optional budget, then track spending, remaining balance, daily activity, and category subtotals.
A4: Selected Month | C4: Monthly Spend | E4: Monthly Budget | G4: Remaining | I4: Top Category
A5: 46235 | C5: =SUMIFS(ExpensesTable[Amount],ExpensesTable[Month Start],A5)+SUMIFS(August2026Expenses[Amount],August2026Expenses[Month Start],A5) -> 95959 | E5: 176500 | G5: =E5-C5 -> 80541 | I5: =IF(C5=0,"No expenses",INDEX(E14:E23,MATCH(MAX(F14:F23),F14:F23,0))) -> Personal
A9: Dashboard totals combine archived August records with new entries from the Expenses sheet. Select a month and enter a budget to refresh the view.
A12: EXPENSES BY MONTH | E12: SUBTOTALS BY CATEGORY | I12: EXPENSES BY DAY | L12: SUBTOTALS BY SUBCATEGORY
A13: Month | B13: Subtotal | C13: % of Selected Month | E13: Category | F13: Subtotal | G13: % of Month | I13: Day | J13: Subtotal | L13: Subcategory | M13: Subtotal | N13: % of Month
A14: 46023 | B14: =SUMIFS(ExpensesTable[Amount],ExpensesTable[Month Start],A14)+SUMIFS(August2026Expenses[Amount],August2026Expenses[Month Start],A14) -> 0 | C14: =IF($C$5=0,0,B14/$C$5) -> 0 | E14: Food | F14: =SUMIFS(ExpensesTable[Amount],ExpensesTable[Category],E14,ExpensesTable[Month Start],$A$5)+SUMIFS(August2026Expenses[Amount],August2026Expenses[Category],E14,August2026Expenses[Month Start],$A$5) -> 4013 | G14: =IF($C$5=0,0,F14/$C$5) -> 0.041819944 | I14: 1 | J14: =SUMIFS(ExpensesTable[Amount],ExpensesTable[Month Start],$A$5,ExpensesTable[Day],I14)+SUMIFS(August2026Expenses[Amount],August2026Expenses[Month Start],$A$5,August2026Expenses[Day],I14) -> 6000 | L14: Groceries | M14: =SUMIFS(ExpensesTable[Amount],ExpensesTable[Subcategory],L14,ExpensesTable[Month Start],$A$5)+SUMIFS(August2026Expenses[Amount],August2026Expenses[Subcategory],L14,August2026Expenses[Month Start],$A$5) -> 5917 | N14: =IF($C$5=0,0,M14/$C$5) -> 0.061661751
A15: 46054 | B15: =SUMIFS(ExpensesTable[Amount],ExpensesTable[Month Start],A15)+SUMIFS(August2026Expenses[Amount],August2026Expenses[Month Start],A15) -> 0 | C15: =IF($C$5=0,0,B15/$C$5) -> 0 | E15: Transport | F15: =SUMIFS(ExpensesTable[Amount],ExpensesTable[Category],E15,ExpensesTable[Month Start],$A$5)+SUMIFS(August2026Expenses[Amount],August2026Expenses[Category],E15,August2026Expenses[Month Start],$A$5) -> 12814 | G15: =IF($C$5=0,0,F15/$C$5) -> 0.1335362 | I15: 2 | J15: =SUMIFS(ExpensesTable[Amount],ExpensesTable[Month Start],$A$5,ExpensesTable[Day],I15)+SUMIFS(August2026Expenses[Amount],August2026Expenses[Month Start],$A$5,August2026Expenses[Day],I15) -> 754 | L15: Dining Out | M15: =SUMIFS(ExpensesTable[Amount],ExpensesTable[Subcategory],L15,ExpensesTable[Month Start],$A$5)+SUMIFS(August2026Expenses[Amount],August2026Expenses[Subcategory],L15,August2026Expenses[Month Start],$A$5) -> 5889 | N15: =IF($C$5=0,0,M15/$C$5) -> 0.06136996
A16: 46082 | B16: =SUMIFS(ExpensesTable[Amount],ExpensesTable[Month Start],A16)+SUMIFS(August2026Expenses[Amount],August2026Expenses[Month Start],A16) -> 0 | C16: =IF($C$5=0,0,B16/$C$5) -> 0 | E16: Utilities | F16: =SUMIFS(ExpensesTable[Amount],ExpensesTable[Category],E16,ExpensesTable[Month Start],$A$5)+SUMIFS(August2026Expenses[Amount],August2026Expenses[Category],E16,August2026Expenses[Month Start],$A$5) -> 7519 | G16: =IF($C$5=0,0,F16/$C$5) -> 0.078356381 | I16: 3 | J16: =SUMIFS(ExpensesTable[Amount],ExpensesTable[Month Start],$A$5,ExpensesTable[Day],I16)+SUMIFS(August2026Expenses[Amount],August2026Expenses[Month Start],$A$5,August2026Expenses[Day],I16) -> 9390 | L16: Coffee/Snacks | M16: =SUMIFS(ExpensesTable[Amount],ExpensesTable[Subcategory],L16,ExpensesTable[Month Start],$A$5)+SUMIFS(August2026Expenses[Amount],August2026Expenses[Subcategory],L16,August2026Expenses[Month Start],$A$5) -> 375 | N16: =IF($C$5=0,0,M16/$C$5) -> 0.003907919
A17: 46113 | B17: =SUMIFS(ExpensesTable[Amount],ExpensesTable[Month Start],A17)+SUMIFS(August2026Expenses[Amount],August2026Expenses[Month Start],A17) -> 0 | C17: =IF($C$5=0,0,B17/$C$5) -> 0 | E17: Housing | F17: =SUMIFS(ExpensesTable[Amount],ExpensesTable[Category],E17,ExpensesTable[Month Start],$A$5)+SUMIFS(August2026Expenses[Amount],August2026Expenses[Category],E17,August2026Expenses[Month Start],$A$5) -> 24754 | G17: =IF($C$5=0,0,F17/$C$5) -> 0.25796434 | I17: 4 | J17: =SUMIFS(ExpensesTable[Amount],ExpensesTable[Month Start],$A$5,ExpensesTable[Day],I17)+SUMIFS(August2026Expenses[Amount],August2026Expenses[Month Start],$A$5,August2026Expenses[Day],I17) -> 100 | L17: Public Transit | M17: =SUMIFS(ExpensesTable[Amount],ExpensesTable[Subcategory],L17,ExpensesTable[Month Start],$A$5)+SUMIFS(August2026Expenses[Amount],August2026Expenses[Subcategory],L17,August2026Expenses[Month Start],$A$5) -> 0 | N17: =IF($C$5=0,0,M17/$C$5) -> 0
A18: 46143 | B18: =SUMIFS(ExpensesTable[Amount],ExpensesTable[Month Start],A18)+SUMIFS(August2026Expenses[Amount],August2026Expenses[Month Start],A18) -> 0 | C18: =IF($C$5=0,0,B18/$C$5) -> 0 | E18: Healthcare | F18: =SUMIFS(ExpensesTable[Amount],ExpensesTable[Category],E18,ExpensesTable[Month Start],$A$5)+SUMIFS(August2026Expenses[Amount],August2026Expenses[Category],E18,August2026Expenses[Month Start],$A$5) -> 0 | G18: =IF($C$5=0,0,F18/$C$5) -> 0 | I18: 5 | J18: =SUMIFS(ExpensesTable[Amount],ExpensesTable[Month Start],$A$5,ExpensesTable[Day],I18)+SUMIFS(August2026Expenses[Amount],August2026Expenses[Month Start],$A$5,August2026Expenses[Day],I18) -> 407 | L18: Ride-hailing | M18: =SUMIFS(ExpensesTable[Amount],ExpensesTable[Subcategory],L18,ExpensesTable[Month Start],$A$5)+SUMIFS(August2026Expenses[Amount],August2026Expenses[Subcategory],L18,August2026Expenses[Month Start],$A$5) -> 1102 | N18: =IF($C$5=0,0,M18/$C$5) -> 0.011484071
A19: 46174 | B19: =SUMIFS(ExpensesTable[Amount],ExpensesTable[Month Start],A19)+SUMIFS(August2026Expenses[Amount],August2026Expenses[Month Start],A19) -> 0 | C19: =IF($C$5=0,0,B19/$C$5) -> 0 | E19: Entertainment | F19: =SUMIFS(ExpensesTable[Amount],ExpensesTable[Category],E19,ExpensesTable[Month Start],$A$5)+SUMIFS(August2026Expenses[Amount],August2026Expenses[Category],E19,August2026Expenses[Month Start],$A$5) -> 3396 | G19: =IF($C$5=0,0,F19/$C$5) -> 0.035390115 | I19: 6 | J19: =SUMIFS(ExpensesTable[Amount],ExpensesTable[Month Start],$A$5,ExpensesTable[Day],I19)+SUMIFS(August2026Expenses[Amount],August2026Expenses[Month Start],$A$5,August2026Expenses[Day],I19) -> 3630 | L19: Fuel | M19: =SUMIFS(ExpensesTable[Amount],ExpensesTable[Subcategory],L19,ExpensesTable[Month Start],$A$5)+SUMIFS(August2026Expenses[Amount],August2026Expenses[Subcategory],L19,August2026Expenses[Month Start],$A$5) -> 5169 | N19: =IF($C$5=0,0,M19/$C$5) -> 0.053866756
A20: 46204 | B20: =SUMIFS(ExpensesTable[Amount],ExpensesTable[Month Start],A20)+SUMIFS(August2026Expenses[Amount],August2026Expenses[Month Start],A20) -> 0 | C20: =IF($C$5=0,0,B20/$C$5) -> 0 | E20: Personal | F20: =SUMIFS(ExpensesTable[Amount],ExpensesTable[Category],E20,ExpensesTable[Month Start],$A$5)+SUMIFS(August2026Expenses[Amount],August2026Expenses[Category],E20,August2026Expenses[Month Start],$A$5) -> 32715 | G20: =IF($C$5=0,0,F20/$C$5) -> 0.34092685 | I20: 7 | J20: =SUMIFS(ExpensesTable[Amount],ExpensesTable[Month Start],$A$5,ExpensesTable[Day],I20)+SUMIFS(August2026Expenses[Amount],August2026Expenses[Month Start],$A$5,August2026Expenses[Day],I20) -> 500 | L20: Electricity | M20: =SUMIFS(ExpensesTable[Amount],ExpensesTable[Subcategory],L20,ExpensesTable[Month Start],$A$5)+SUMIFS(August2026Expenses[Amount],August2026Expenses[Subcategory],L20,August2026Expenses[Month Start],$A$5) -> 5821 | N20: =IF($C$5=0,0,M20/$C$5) -> 0.060661324
A21: 46235 | B21: =SUMIFS(ExpensesTable[Amount],ExpensesTable[Month Start],A21)+SUMIFS(August2026Expenses[Amount],August2026Expenses[Month Start],A21) -> 95959 | C21: =IF($C$5=0,0,B21/$C$5) -> 1 | E21: Savings | F21: =SUMIFS(ExpensesTable[Amount],ExpensesTable[Category],E21,ExpensesTable[Month Start],$A$5)+SUMIFS(August2026Expenses[Amount],August2026Expenses[Category],E21,August2026Expenses[Month Start],$A$5) -> 0 | G21: =IF($C$5=0,0,F21/$C$5) -> 0 | I21: 8 | J21: =SUMIFS(ExpensesTable[Amount],ExpensesTable[Month Start],$A$5,ExpensesTable[Day],I21)+SUMIFS(August2026Expenses[Amount],August2026Expenses[Month Start],$A$5,August2026Expenses[Day],I21) -> 1920 | L21: Water | M21: =SUMIFS(ExpensesTable[Amount],ExpensesTable[Subcategory],L21,ExpensesTable[Month Start],$A$5)+SUMIFS(August2026Expenses[Amount],August2026Expenses[Subcategory],L21,August2026Expenses[Month Start],$A$5) -> 0 | N21: =IF($C$5=0,0,M21/$C$5) -> 0
A22: 46266 | B22: =SUMIFS(ExpensesTable[Amount],ExpensesTable[Month Start],A22)+SUMIFS(August2026Expenses[Amount],August2026Expenses[Month Start],A22) -> 0 | C22: =IF($C$5=0,0,B22/$C$5) -> 0 | E22: Other | F22: =SUMIFS(ExpensesTable[Amount],ExpensesTable[Category],E22,ExpensesTable[Month Start],$A$5)+SUMIFS(August2026Expenses[Amount],August2026Expenses[Category],E22,August2026Expenses[Month Start],$A$5) -> 1390 | G22: =IF($C$5=0,0,F22/$C$5) -> 0.014485353 | I22: 9 | J22: =SUMIFS(ExpensesTable[Amount],ExpensesTable[Month Start],$A$5,ExpensesTable[Day],I22)+SUMIFS(August2026Expenses[Amount],August2026Expenses[Month Start],$A$5,August2026Expenses[Day],I22) -> 11337 | L22: Internet | M22: =SUMIFS(ExpensesTable[Amount],ExpensesTable[Subcategory],L22,ExpensesTable[Month Start],$A$5)+SUMIFS(August2026Expenses[Amount],August2026Expenses[Subcategory],L22,August2026Expenses[Month Start],$A$5) -> 1698 | N22: =IF($C$5=0,0,M22/$C$5) -> 0.017695057
A23: 46296 | B23: =SUMIFS(ExpensesTable[Amount],ExpensesTable[Month Start],A23)+SUMIFS(August2026Expenses[Amount],August2026Expenses[Month Start],A23) -> 0 | C23: =IF($C$5=0,0,B23/$C$5) -> 0 | E23: Grab | F23: =SUMIFS(ExpensesTable[Amount],ExpensesTable[Category],E23,ExpensesTable[Month Start],$A$5)+SUMIFS(August2026Expenses[Amount],August2026Expenses[Category],E23,August2026Expenses[Month Start],$A$5) -> 7558 | G23: =IF($C$5=0,0,F23/$C$5) -> 0.078762805 | I23: 10 | J23: =SUMIFS(ExpensesTable[Amount],ExpensesTable[Month Start],$A$5,ExpensesTable[Day],I23)+SUMIFS(August2026Expenses[Amount],August2026Expenses[Month Start],$A$5,August2026Expenses[Day],I23) -> 1800 | L23: Mobile | M23: =SUMIFS(ExpensesTable[Amount],ExpensesTable[Subcategory],L23,ExpensesTable[Month Start],$A$5)+SUMIFS(August2026Expenses[Amount],August2026Expenses[Subcategory],L23,August2026Expenses[Month Start],$A$5) -> 0 | N23: =IF($C$5=0,0,M23/$C$5) -> 0
A24: 46327 | B24: =SUMIFS(ExpensesTable[Amount],ExpensesTable[Month Start],A24)+SUMIFS(August2026Expenses[Amount],August2026Expenses[Month Start],A24) -> 0 | C24: =IF($C$5=0,0,B24/$C$5) -> 0 | I24: 11 | J24: =SUMIFS(ExpensesTable[Amount],ExpensesTable[Month Start],$A$5,ExpensesTable[Day],I24)+SUMIFS(August2026Expenses[Amount],August2026Expenses[Month Start],$A$5,August2026Expenses[Day],I24) -> 0 | L24: Rent | M24: =SUMIFS(ExpensesTable[Amount],ExpensesTable[Subcategory],L24,ExpensesTable[Month Start],$A$5)+SUMIFS(August2026Expenses[Amount],August2026Expenses[Subcategory],L24,August2026Expenses[Month Start],$A$5) -> 4500 | N24: =IF($C$5=0,0,M24/$C$5) -> 0.046895028
A25: 46357 | B25: =SUMIFS(ExpensesTable[Amount],ExpensesTable[Month Start],A25)+SUMIFS(August2026Expenses[Amount],August2026Expenses[Month Start],A25) -> 0 | C25: =IF($C$5=0,0,B25/$C$5) -> 0 | I25: 12 | J25: =SUMIFS(ExpensesTable[Amount],ExpensesTable[Month Start],$A$5,ExpensesTable[Day],I25)+SUMIFS(August2026Expenses[Amount],August2026Expenses[Month Start],$A$5,August2026Expenses[Day],I25) -> 3797 | L25: Mortgage | M25: =SUMIFS(ExpensesTable[Amount],ExpensesTable[Subcategory],L25,ExpensesTable[Month Start],$A$5)+SUMIFS(August2026Expenses[Amount],August2026Expenses[Subcategory],L25,August2026Expenses[Month Start],$A$5) -> 17200 | N25: =IF($C$5=0,0,M25/$C$5) -> 0.17924322
I26: 13 | J26: =SUMIFS(ExpensesTable[Amount],ExpensesTable[Month Start],$A$5,ExpensesTable[Day],I26)+SUMIFS(August2026Expenses[Amount],August2026Expenses[Month Start],$A$5,August2026Expenses[Day],I26) -> 21600 | L26: Repairs | M26: =SUMIFS(ExpensesTable[Amount],ExpensesTable[Subcategory],L26,ExpensesTable[Month Start],$A$5)+SUMIFS(August2026Expenses[Amount],August2026Expenses[Subcategory],L26,August2026Expenses[Month Start],$A$5) -> 1150 | N26: =IF($C$5=0,0,M26/$C$5) -> 0.011984285
I27: 14 | J27: =SUMIFS(ExpensesTable[Amount],ExpensesTable[Month Start],$A$5,ExpensesTable[Day],I27)+SUMIFS(August2026Expenses[Amount],August2026Expenses[Month Start],$A$5,August2026Expenses[Day],I27) -> 4441 | L27: Medicine | M27: =SUMIFS(ExpensesTable[Amount],ExpensesTable[Subcategory],L27,ExpensesTable[Month Start],$A$5)+SUMIFS(August2026Expenses[Amount],August2026Expenses[Subcategory],L27,August2026Expenses[Month Start],$A$5) -> 0 | N27: =IF($C$5=0,0,M27/$C$5) -> 0
I28: 15 | J28: =SUMIFS(ExpensesTable[Amount],ExpensesTable[Month Start],$A$5,ExpensesTable[Day],I28)+SUMIFS(August2026Expenses[Amount],August2026Expenses[Month Start],$A$5,August2026Expenses[Day],I28) -> 0 | L28: Doctor | M28: =SUMIFS(ExpensesTable[Amount],ExpensesTable[Subcategory],L28,ExpensesTable[Month Start],$A$5)+SUMIFS(August2026Expenses[Amount],August2026Expenses[Subcategory],L28,August2026Expenses[Month Start],$A$5) -> 0 | N28: =IF($C$5=0,0,M28/$C$5) -> 0
I29: 16 | J29: =SUMIFS(ExpensesTable[Amount],ExpensesTable[Month Start],$A$5,ExpensesTable[Day],I29)+SUMIFS(August2026Expenses[Amount],August2026Expenses[Month Start],$A$5,August2026Expenses[Day],I29) -> 7625 | L29: Insurance | M29: =SUMIFS(ExpensesTable[Amount],ExpensesTable[Subcategory],L29,ExpensesTable[Month Start],$A$5)+SUMIFS(August2026Expenses[Amount],August2026Expenses[Subcategory],L29,August2026Expenses[Month Start],$A$5) -> 0 | N29: =IF($C$5=0,0,M29/$C$5) -> 0
I30: 17 | J30: =SUMIFS(ExpensesTable[Amount],ExpensesTable[Month Start],$A$5,ExpensesTable[Day],I30)+SUMIFS(August2026Expenses[Amount],August2026Expenses[Month Start],$A$5,August2026Expenses[Day],I30) -> 2259 | L30: Movies | M30: =SUMIFS(ExpensesTable[Amount],ExpensesTable[Subcategory],L30,ExpensesTable[Month Start],$A$5)+SUMIFS(August2026Expenses[Amount],August2026Expenses[Subcategory],L30,August2026Expenses[Month Start],$A$5) -> 1000 | N30: =IF($C$5=0,0,M30/$C$5) -> 0.010421117
I31: 18 | J31: =SUMIFS(ExpensesTable[Amount],ExpensesTable[Month Start],$A$5,ExpensesTable[Day],I31)+SUMIFS(August2026Expenses[Amount],August2026Expenses[Month Start],$A$5,August2026Expenses[Day],I31) -> 0 | L31: Subscriptions | M31: =SUMIFS(ExpensesTable[Amount],ExpensesTable[Subcategory],L31,ExpensesTable[Month Start],$A$5)+SUMIFS(August2026Expenses[Amount],August2026Expenses[Subcategory],L31,August2026Expenses[Month Start],$A$5) -> 3778 | N31: =IF($C$5=0,0,M31/$C$5) -> 0.039370981
I32: 19 | J32: =SUMIFS(ExpensesTable[Amount],ExpensesTable[Month Start],$A$5,ExpensesTable[Day],I32)+SUMIFS(August2026Expenses[Amount],August2026Expenses[Month Start],$A$5,August2026Expenses[Day],I32) -> 0 | L32: Shopping | M32: =SUMIFS(ExpensesTable[Amount],ExpensesTable[Subcategory],L32,ExpensesTable[Month Start],$A$5)+SUMIFS(August2026Expenses[Amount],August2026Expenses[Subcategory],L32,August2026Expenses[Month Start],$A$5) -> 3663 | N32: =IF($C$5=0,0,M32/$C$5) -> 0.038172553
I33: 20 | J33: =SUMIFS(ExpensesTable[Amount],ExpensesTable[Month Start],$A$5,ExpensesTable[Day],I33)+SUMIFS(August2026Expenses[Amount],August2026Expenses[Month Start],$A$5,August2026Expenses[Day],I33) -> 0 | L33: Clothing | M33: =SUMIFS(ExpensesTable[Amount],ExpensesTable[Subcategory],L33,ExpensesTable[Month Start],$A$5)+SUMIFS(August2026Expenses[Amount],August2026Expenses[Subcategory],L33,August2026Expenses[Month Start],$A$5) -> 3500 | N33: =IF($C$5=0,0,M33/$C$5) -> 0.036473911
I34: 21 | J34: =SUMIFS(ExpensesTable[Amount],ExpensesTable[Month Start],$A$5,ExpensesTable[Day],I34)+SUMIFS(August2026Expenses[Amount],August2026Expenses[Month Start],$A$5,August2026Expenses[Day],I34) -> 7904 | L34: Self-care | M34: =SUMIFS(ExpensesTable[Amount],ExpensesTable[Subcategory],L34,ExpensesTable[Month Start],$A$5)+SUMIFS(August2026Expenses[Amount],August2026Expenses[Subcategory],L34,August2026Expenses[Month Start],$A$5) -> 7319 | N34: =IF($C$5=0,0,M34/$C$5) -> 0.076272158
I35: 22 | J35: =SUMIFS(ExpensesTable[Amount],ExpensesTable[Month Start],$A$5,ExpensesTable[Day],I35)+SUMIFS(August2026Expenses[Amount],August2026Expenses[Month Start],$A$5,August2026Expenses[Day],I35) -> 0 | L35: Emergency Fund | M35: =SUMIFS(ExpensesTable[Amount],ExpensesTable[Subcategory],L35,ExpensesTable[Month Start],$A$5)+SUMIFS(August2026Expenses[Amount],August2026Expenses[Subcategory],L35,August2026Expenses[Month Start],$A$5) -> 0 | N35: =IF($C$5=0,0,M35/$C$5) -> 0
I36: 23 | J36: =SUMIFS(ExpensesTable[Amount],ExpensesTable[Month Start],$A$5,ExpensesTable[Day],I36)+SUMIFS(August2026Expenses[Amount],August2026Expenses[Month Start],$A$5,August2026Expenses[Day],I36) -> 0 | L36: Other | M36: =SUMIFS(ExpensesTable[Amount],ExpensesTable[Subcategory],L36,ExpensesTable[Month Start],$A$5)+SUMIFS(August2026Expenses[Amount],August2026Expenses[Subcategory],L36,August2026Expenses[Month Start],$A$5) -> 3327 | N36: =IF($C$5=0,0,M36/$C$5) -> 0.034671057
I37: 24 | J37: =SUMIFS(ExpensesTable[Amount],ExpensesTable[Month Start],$A$5,ExpensesTable[Day],I37)+SUMIFS(August2026Expenses[Amount],August2026Expenses[Month Start],$A$5,August2026Expenses[Day],I37) -> 1520 | L37: Food | M37: =SUMIFS(ExpensesTable[Amount],ExpensesTable[Subcategory],L37,ExpensesTable[Month Start],$A$5)+SUMIFS(August2026Expenses[Amount],August2026Expenses[Subcategory],L37,August2026Expenses[Month Start],$A$5) -> 6356 | N37: =IF($C$5=0,0,M37/$C$5) -> 0.066236622
... I40: 27 | J40: =SUMIFS(ExpensesTable[Amount],ExpensesTable[Month Start],$A$5,ExpensesTable[Day],I40)+SUMIFS(August2026Expenses[Amount],August2026Expenses[Month Start],$A$5,August2026Expenses[Day],I40) -> 1698 | L40: Pet | M40: =SUMIFS(ExpensesTable[Amount],ExpensesTable[Subcategory],L40,ExpensesTable[Month Start],$A$5)+SUMIFS(August2026Expenses[Amount],August2026Expenses[Subcategory],L40,August2026Expenses[Month Start],$A$5) -> 1350 | N40: =IF($C$5=0,0,M40/$C$5) -> 0.014068508
I41: 28 | J41: =SUMIFS(ExpensesTable[Amount],ExpensesTable[Month Start],$A$5,ExpensesTable[Day],I41)+SUMIFS(August2026Expenses[Amount],August2026Expenses[Month Start],$A$5,August2026Expenses[Day],I41) -> 5821
I42: 29 | J42: =SUMIFS(ExpensesTable[Amount],ExpensesTable[Month Start],$A$5,ExpensesTable[Day],I42)+SUMIFS(August2026Expenses[Amount],August2026Expenses[Month Start],$A$5,August2026Expenses[Day],I42) -> 0
I43: 30 | J43: =SUMIFS(ExpensesTable[Amount],ExpensesTable[Month Start],$A$5,ExpensesTable[Day],I43)+SUMIFS(August2026Expenses[Amount],August2026Expenses[Month Start],$A$5,August2026Expenses[Day],I43) -> 3456
I44: 31 | J44: =SUMIFS(ExpensesTable[Amount],ExpensesTable[Month Start],$A$5,ExpensesTable[Day],I44)+SUMIFS(August2026Expenses[Amount],August2026Expenses[Month Start],$A$5,August2026Expenses[Day],I44) -> 0

Sheet Expenses
A1: Monthly Expense Tracker | J1: Category List | K1: Subcategory List
A2: Add expenses in columns A:E only. Use dropdowns for Category/Subcategory; the dashboard updates automatically. | J2: Food | K2: Groceries
J3: Transport | K3: Dining Out
A4: Date | B4: Bills | C4: Amount | D4: Category | E4: Subcategory | F4: Month Start | G4: Day | J4: Utilities | K4: Coffee/Snacks
A5: 46247 | B5: Avida Almiera Lot | C5: 11200 | D5: Housing | E5: Mortgage | F5: =IF(ExpensesTable[[#This Row],[Date]]="","",DATE(YEAR(ExpensesTable[[#This Row],[Date]]),MONTH(ExpensesTable[[#This Row],[Date]]),1)) -> 46235 | G5: =IF(ExpensesTable[[#This Row],[Date]]="","",DAY(ExpensesTable[[#This Row],[Date]])) -> 13 | J5: Housing | K5: Public Transit
A6: 46247 | B6: Wife Allowance | C6: 500 | D6: Personal | E6: Allowance | F6: =IF(ExpensesTable[[#This Row],[Date]]="","",DATE(YEAR(ExpensesTable[[#This Row],[Date]]),MONTH(ExpensesTable[[#This Row],[Date]]),1)) -> 46235 | G6: =IF(ExpensesTable[[#This Row],[Date]]="","",DAY(ExpensesTable[[#This Row],[Date]])) -> 13 | J6: Healthcare | K6: Ride-hailing
A7: 46247 | B7: Wife Allowance | C7: 7500 | D7: Personal | E7: Allowance | F7: =IF(ExpensesTable[[#This Row],[Date]]="","",DATE(YEAR(ExpensesTable[[#This Row],[Date]]),MONTH(ExpensesTable[[#This Row],[Date]]),1)) -> 46235 | G7: =IF(ExpensesTable[[#This Row],[Date]]="","",DAY(ExpensesTable[[#This Row],[Date]])) -> 13 | J7: Entertainment | K7: Fuel
A8: 46247 | B8: Anytime Fitness -wife | C8: 2400 | D8: Personal | E8: Self-care | F8: =IF(ExpensesTable[[#This Row],[Date]]="","",DATE(YEAR(ExpensesTable[[#This Row],[Date]]),MONTH(ExpensesTable[[#This Row],[Date]]),1)) -> 46235 | G8: =IF(ExpensesTable[[#This Row],[Date]]="","",DAY(ExpensesTable[[#This Row],[Date]])) -> 13 | J8: Personal | K8: Electricity
A9: 46248 | B9: Vape | C9: 1160 | D9: Personal | E9: Other | F9: =IF(ExpensesTable[[#This Row],[Date]]="","",DATE(YEAR(ExpensesTable[[#This Row],[Date]]),MONTH(ExpensesTable[[#This Row],[Date]]),1)) -> 46235 | G9: =IF(ExpensesTable[[#This Row],[Date]]="","",DAY(ExpensesTable[[#This Row],[Date]])) -> 14 | J9: Savings | K9: Water
A10: 46248 | B10: Globe Load | C10: 100 | D10: Personal | E10: Subscriptions | F10: =IF(ExpensesTable[[#This Row],[Date]]="","",DATE(YEAR(ExpensesTable[[#This Row],[Date]]),MONTH(ExpensesTable[[#This Row],[Date]]),1)) -> 46235 | G10: =IF(ExpensesTable[[#This Row],[Date]]="","",DAY(ExpensesTable[[#This Row],[Date]])) -> 14 | J10: Other | K10: Internet
A11: 46248 | B11: Google Prime Video | C11: 149 | D11: Entertainment | E11: Subscriptions | F11: =IF(ExpensesTable[[#This Row],[Date]]="","",DATE(YEAR(ExpensesTable[[#This Row],[Date]]),MONTH(ExpensesTable[[#This Row],[Date]]),1)) -> 46235 | G11: =IF(ExpensesTable[[#This Row],[Date]]="","",DAY(ExpensesTable[[#This Row],[Date]])) -> 14 | J11: Grab | K11: Mobile
A12: 46248 | B12: Savemore Acacia | C12: 2332 | D12: Housing | E12: Groceries | F12: =IF(ExpensesTable[[#This Row],[Date]]="","",DATE(YEAR(ExpensesTable[[#This Row],[Date]]),MONTH(ExpensesTable[[#This Row],[Date]]),1)) -> 46235 | G12: =IF(ExpensesTable[[#This Row],[Date]]="","",DAY(ExpensesTable[[#This Row],[Date]])) -> 14 | K12: Rent
A13: 46248 | B13: Crunchyroll | C13: 700 | D13: Personal | E13: Subscriptions | F13: =IF(ExpensesTable[[#This Row],[Date]]="","",DATE(YEAR(ExpensesTable[[#This Row],[Date]]),MONTH(ExpensesTable[[#This Row],[Date]]),1)) -> 46235 | G13: =IF(ExpensesTable[[#This Row],[Date]]="","",DAY(ExpensesTable[[#This Row],[Date]])) -> 14 | K13: Mortgage
A14: 46250 | B14: Oh Mango | C14: 561 | D14: Grab | E14: Food | F14: =IF(ExpensesTable[[#This Row],[Date]]="","",DATE(YEAR(ExpensesTable[[#This Row],[Date]]),MONTH(ExpensesTable[[#This Row],[Date]]),1)) -> 46235 | G14: =IF(ExpensesTable[[#This Row],[Date]]="","",DAY(ExpensesTable[[#This Row],[Date]])) -> 16 | K14: Repairs
A15: 46250 | B15: Wife Allowance | C15: 1154 | D15: Personal | E15: Allowance | F15: =IF(ExpensesTable[[#This Row],[Date]]="","",DATE(YEAR(ExpensesTable[[#This Row],[Date]]),MONTH(ExpensesTable[[#This Row],[Date]]),1)) -> 46235 | G15: =IF(ExpensesTable[[#This Row],[Date]]="","",DAY(ExpensesTable[[#This Row],[Date]])) -> 16 | K15: Medicine
A16: 46250 | B16: Parking Rent | C16: 4500 | D16: Transport | E16: Rent | F16: =IF(ExpensesTable[[#This Row],[Date]]="","",DATE(YEAR(ExpensesTable[[#This Row],[Date]]),MONTH(ExpensesTable[[#This Row],[Date]]),1)) -> 46235 | G16: =IF(ExpensesTable[[#This Row],[Date]]="","",DAY(ExpensesTable[[#This Row],[Date]])) -> 16 | K16: Doctor
A17: 46250 | B17: Car Wash | C17: 1150 | D17: Transport | E17: Repairs | F17: =IF(ExpensesTable[[#This Row],[Date]]="","",DATE(YEAR(ExpensesTable[[#This Row],[Date]]),MONTH(ExpensesTable[[#This Row],[Date]]),1)) -> 46235 | G17: =IF(ExpensesTable[[#This Row],[Date]]="","",DAY(ExpensesTable[[#This Row],[Date]])) -> 16 | K17: Insurance
A18: 46250 | B18: Watson Tsyani | C18: 140 | D18: Other | E18: Shopping | F18: =IF(ExpensesTable[[#This Row],[Date]]="","",DATE(YEAR(ExpensesTable[[#This Row],[Date]]),MONTH(ExpensesTable[[#This Row],[Date]]),1)) -> 46235 | G18: =IF(ExpensesTable[[#This Row],[Date]]="","",DAY(ExpensesTable[[#This Row],[Date]])) -> 16 | K18: Movies
A19: 46250 | B19: Turks | C19: 120 | D19: Food | E19: Coffee/Snacks | F19: =IF(ExpensesTable[[#This Row],[Date]]="","",DATE(YEAR(ExpensesTable[[#This Row],[Date]]),MONTH(ExpensesTable[[#This Row],[Date]]),1)) -> 46235 | G19: =IF(ExpensesTable[[#This Row],[Date]]="","",DAY(ExpensesTable[[#This Row],[Date]])) -> 16 | K19: Subscriptions
A20: 46251 | B20: Muji Coffee | C20: 160 | D20: Food | E20: Coffee/Snacks | F20: =IF(ExpensesTable[[#This Row],[Date]]="","",DATE(YEAR(ExpensesTable[[#This Row],[Date]]),MONTH(ExpensesTable[[#This Row],[Date]]),1)) -> 46235 | G20: =IF(ExpensesTable[[#This Row],[Date]]="","",DAY(ExpensesTable[[#This Row],[Date]])) -> 17 | K20: Shopping
A21: 46251 | B21: Blade Asia | C21: 768 | D21: Transport | E21: Other | F21: =IF(ExpensesTable[[#This Row],[Date]]="","",DATE(YEAR(ExpensesTable[[#This Row],[Date]]),MONTH(ExpensesTable[[#This Row],[Date]]),1)) -> 46235 | G21: =IF(ExpensesTable[[#This Row],[Date]]="","",DAY(ExpensesTable[[#This Row],[Date]])) -> 17 | K21: Clothing
A22: 46251 | B22: Grab Car | C22: 502 | D22: Grab | E22: Ride-hailing | F22: =IF(ExpensesTable[[#This Row],[Date]]="","",DATE(YEAR(ExpensesTable[[#This Row],[Date]]),MONTH(ExpensesTable[[#This Row],[Date]]),1)) -> 46235 | G22: =IF(ExpensesTable[[#This Row],[Date]]="","",DAY(ExpensesTable[[#This Row],[Date]])) -> 17 | K22: Self-care
A23: 46251 | B23: Grab Car | C23: 600 | D23: Grab | E23: Ride-hailing | F23: =IF(ExpensesTable[[#This Row],[Date]]="","",DATE(YEAR(ExpensesTable[[#This Row],[Date]]),MONTH(ExpensesTable[[#This Row],[Date]]),1)) -> 46235 | G23: =IF(ExpensesTable[[#This Row],[Date]]="","",DAY(ExpensesTable[[#This Row],[Date]])) -> 17 | K23: Emergency Fund
... A28: 46255 | B28: Samgyup Mr Corea | C28: 2032 | D28: Food | E28: Dining Out | F28: =IF(ExpensesTable[[#This Row],[Date]]="","",DATE(YEAR(ExpensesTable[[#This Row],[Date]]),MONTH(ExpensesTable[[#This Row],[Date]]),1)) -> 46235 | G28: =IF(ExpensesTable[[#This Row],[Date]]="","",DAY(ExpensesTable[[#This Row],[Date]])) -> 21 | K28: Pet
A29: 46255 | B29: Scent Smith | C29: 2296 | D29: Personal | E29: Shopping | F29: =IF(ExpensesTable[[#This Row],[Date]]="","",DATE(YEAR(ExpensesTable[[#This Row],[Date]]),MONTH(ExpensesTable[[#This Row],[Date]]),1)) -> 46235 | G29: =IF(ExpensesTable[[#This Row],[Date]]="","",DAY(ExpensesTable[[#This Row],[Date]])) -> 21
A30: 46258 | B30: Grab Food | C30: 722 | D30: Grab | E30: Food | F30: =IF(ExpensesTable[[#This Row],[Date]]="","",DATE(YEAR(ExpensesTable[[#This Row],[Date]]),MONTH(ExpensesTable[[#This Row],[Date]]),1)) -> 46235 | G30: =IF(ExpensesTable[[#This Row],[Date]]="","",DAY(ExpensesTable[[#This Row],[Date]])) -> 24
A31: 46258 | B31: Grab Food | C31: 798 | D31: Grab | E31: Food | F31: =IF(ExpensesTable[[#This Row],[Date]]="","",DATE(YEAR(ExpensesTable[[#This Row],[Date]]),MONTH(ExpensesTable[[#This Row],[Date]]),1)) -> 46235 | G31: =IF(ExpensesTable[[#This Row],[Date]]="","",DAY(ExpensesTable[[#This Row],[Date]])) -> 24
A32: 46261 | B32: Globe Billspay | C32: 1698 | D32: Utilities | E32: Internet | F32: =IF(ExpensesTable[[#This Row],[Date]]="","",DATE(YEAR(ExpensesTable[[#This Row],[Date]]),MONTH(ExpensesTable[[#This Row],[Date]]),1)) -> 46235 | G32: =IF(ExpensesTable[[#This Row],[Date]]="","",DAY(ExpensesTable[[#This Row],[Date]])) -> 27
A33: 46262 | B33: Meralco | C33: 5821 | D33: Utilities | E33: Electricity | F33: =IF(ExpensesTable[[#This Row],[Date]]="","",DATE(YEAR(ExpensesTable[[#This Row],[Date]]),MONTH(ExpensesTable[[#This Row],[Date]]),1)) -> 46235 | G33: =IF(ExpensesTable[[#This Row],[Date]]="","",DAY(ExpensesTable[[#This Row],[Date]])) -> 28
A34: 46264 | B34: Egg and food | C34: 500 | D34: Personal | E34: Other | F34: =IF(ExpensesTable[[#This Row],[Date]]="","",DATE(YEAR(ExpensesTable[[#This Row],[Date]]),MONTH(ExpensesTable[[#This Row],[Date]]),1)) -> 46235 | G34: =IF(ExpensesTable[[#This Row],[Date]]="","",DAY(ExpensesTable[[#This Row],[Date]])) -> 30
A35: 46264 | B35: Enshrouded Games | C35: 899 | D35: Entertainment | E35: Other | F35: =IF(ExpensesTable[[#This Row],[Date]]="","",DATE(YEAR(ExpensesTable[[#This Row],[Date]]),MONTH(ExpensesTable[[#This Row],[Date]]),1)) -> 46235 | G35: =IF(ExpensesTable[[#This Row],[Date]]="","",DAY(ExpensesTable[[#This Row],[Date]])) -> 30
A36: 46264 | B36: Arabiana food | C36: 883 | D36: Grab | E36: Food | F36: =IF(ExpensesTable[[#This Row],[Date]]="","",DATE(YEAR(ExpensesTable[[#This Row],[Date]]),MONTH(ExpensesTable[[#This Row],[Date]]),1)) -> 46235 | G36: =IF(ExpensesTable[[#This Row],[Date]]="","",DAY(ExpensesTable[[#This Row],[Date]])) -> 30
A37: 46264 | B37: Liquor and chips | C37: 1079 | D37: Grab | E37: Food | F37: =IF(ExpensesTable[[#This Row],[Date]]="","",DATE(YEAR(ExpensesTable[[#This Row],[Date]]),MONTH(ExpensesTable[[#This Row],[Date]]),1)) -> 46235 | G37: =IF(ExpensesTable[[#This Row],[Date]]="","",DAY(ExpensesTable[[#This Row],[Date]])) -> 30
A38: 46264 | B38: Zus | C38: 95 | D38: Personal | E38: Coffee/Snacks | F38: =IF(ExpensesTable[[#This Row],[Date]]="","",DATE(YEAR(ExpensesTable[[#This Row],[Date]]),MONTH(ExpensesTable[[#This Row],[Date]]),1)) -> 46235 | G38: =IF(ExpensesTable[[#This Row],[Date]]="","",DAY(ExpensesTable[[#This Row],[Date]])) -> 30
B39: Anytime Fitness -wife | C39: 2385 | F39: =IF(ExpensesTable[[#This Row],[Date]]="","",DATE(YEAR(ExpensesTable[[#This Row],[Date]]),MONTH(ExpensesTable[[#This Row],[Date]]),1)) | G39: =IF(ExpensesTable[[#This Row],[Date]]="","",DAY(ExpensesTable[[#This Row],[Date]]))
B40: Gym Clothes | C40: 2600 | F40: =IF(ExpensesTable[[#This Row],[Date]]="","",DATE(YEAR(ExpensesTable[[#This Row],[Date]]),MONTH(ExpensesTable[[#This Row],[Date]]),1)) | G40: =IF(ExpensesTable[[#This Row],[Date]]="","",DAY(ExpensesTable[[#This Row],[Date]]))
F41: =IF(ExpensesTable[[#This Row],[Date]]="","",DATE(YEAR(ExpensesTable[[#This Row],[Date]]),MONTH(ExpensesTable[[#This Row],[Date]]),1)) | G41: =IF(ExpensesTable[[#This Row],[Date]]="","",DAY(ExpensesTable[[#This Row],[Date]]))
F42: =IF(ExpensesTable[[#This Row],[Date]]="","",DATE(YEAR(ExpensesTable[[#This Row],[Date]]),MONTH(ExpensesTable[[#This Row],[Date]]),1)) | G42: =IF(ExpensesTable[[#This Row],[Date]]="","",DAY(ExpensesTable[[#This Row],[Date]]))
F43: =IF(ExpensesTable[[#This Row],[Date]]="","",DATE(YEAR(ExpensesTable[[#This Row],[Date]]),MONTH(ExpensesTable[[#This Row],[Date]]),1)) | G43: =IF(ExpensesTable[[#This Row],[Date]]="","",DAY(ExpensesTable[[#This Row],[Date]]))
F44: =IF(ExpensesTable[[#This Row],[Date]]="","",DATE(YEAR(ExpensesTable[[#This Row],[Date]]),MONTH(ExpensesTable[[#This Row],[Date]]),1)) | G44: =IF(ExpensesTable[[#This Row],[Date]]="","",DAY(ExpensesTable[[#This Row],[Date]]))
...

Sheet August 2026 Archive
A1: August 2026 Expense Archive | J1: Category List | K1: Subcategory List
A2: Archived expense records for August 1–12, 2026. This sheet is retained for historical reference. | J2: Food | K2: Groceries
J3: Transport | K3: Dining Out
A4: Date | B4: Bills | C4: Amount | D4: Category | E4: Subcategory | F4: Month Start | G4: Day | J4: Utilities | K4: Coffee/Snacks
A5: 46235 | B5: Condo Amortization | C5: 6000 | D5: Housing | E5: Mortgage | F5: =IF(August2026Expenses[[#This Row],[Date]]="","",DATE(YEAR(August2026Expenses[[#This Row],[Date]]),MONTH(August2026Expenses[[#This Row],[Date]]),1)) -> 46235 | G5: =IF(August2026Expenses[[#This Row],[Date]]="","",DAY(August2026Expenses[[#This Row],[Date]])) -> 1 | J5: Housing | K5: Public Transit
A6: 46236 | B6: Oh Mango | C6: 754 | D6: Grab | E6: Food | F6: =IF(August2026Expenses[[#This Row],[Date]]="","",DATE(YEAR(August2026Expenses[[#This Row],[Date]]),MONTH(August2026Expenses[[#This Row],[Date]]),1)) -> 46235 | G6: =IF(August2026Expenses[[#This Row],[Date]]="","",DAY(August2026Expenses[[#This Row],[Date]])) -> 2 | J6: Healthcare | K6: Ride-hailing
A7: 46237 | B7: Shell Cayetano | C7: 1629 | D7: Transport | E7: Fuel | F7: =IF(August2026Expenses[[#This Row],[Date]]="","",DATE(YEAR(August2026Expenses[[#This Row],[Date]]),MONTH(August2026Expenses[[#This Row],[Date]]),1)) -> 46235 | G7: =IF(August2026Expenses[[#This Row],[Date]]="","",DAY(August2026Expenses[[#This Row],[Date]])) -> 3 | J7: Entertainment | K7: Fuel
A8: 46237 | B8: Shell Supermarket | C8: 353 | D8: Housing | E8: Groceries | F8: =IF(August2026Expenses[[#This Row],[Date]]="","",DATE(YEAR(August2026Expenses[[#This Row],[Date]]),MONTH(August2026Expenses[[#This Row],[Date]]),1)) -> 46235 | G8: =IF(August2026Expenses[[#This Row],[Date]]="","",DAY(August2026Expenses[[#This Row],[Date]])) -> 3 | J8: Personal | K8: Electricity
A9: 46237 | B9: Pepper lunch | C9: 1154 | D9: Personal | E9: Dining Out | F9: =IF(August2026Expenses[[#This Row],[Date]]="","",DATE(YEAR(August2026Expenses[[#This Row],[Date]]),MONTH(August2026Expenses[[#This Row],[Date]]),1)) -> 46235 | G9: =IF(August2026Expenses[[#This Row],[Date]]="","",DAY(August2026Expenses[[#This Row],[Date]])) -> 3 | J9: Savings | K9: Water
A10: 46237 | B10: Puregold | C10: 754 | D10: Housing | E10: Groceries | F10: =IF(August2026Expenses[[#This Row],[Date]]="","",DATE(YEAR(August2026Expenses[[#This Row],[Date]]),MONTH(August2026Expenses[[#This Row],[Date]]),1)) -> 46235 | G10: =IF(August2026Expenses[[#This Row],[Date]]="","",DAY(August2026Expenses[[#This Row],[Date]])) -> 3 | J10: Other | K10: Internet
A11: 46237 | B11: Rebook Training Shoes | C11: 3500 | D11: Personal | E11: Clothing | F11: =IF(August2026Expenses[[#This Row],[Date]]="","",DATE(YEAR(August2026Expenses[[#This Row],[Date]]),MONTH(August2026Expenses[[#This Row],[Date]]),1)) -> 46235 | G11: =IF(August2026Expenses[[#This Row],[Date]]="","",DAY(August2026Expenses[[#This Row],[Date]])) -> 3 | J11: Grab | K11: Mobile
A12: 46237 | B12: Groceries | C12: 2000 | D12: Housing | E12: Groceries | F12: =IF(August2026Expenses[[#This Row],[Date]]="","",DATE(YEAR(August2026Expenses[[#This Row],[Date]]),MONTH(August2026Expenses[[#This Row],[Date]]),1)) -> 46235 | G12: =IF(August2026Expenses[[#This Row],[Date]]="","",DAY(August2026Expenses[[#This Row],[Date]])) -> 3 | K12: Rent
A13: 46238 | B13: Globe Load | C13: 100 | D13: Personal | E13: Subscriptions | F13: =IF(August2026Expenses[[#This Row],[Date]]="","",DATE(YEAR(August2026Expenses[[#This Row],[Date]]),MONTH(August2026Expenses[[#This Row],[Date]]),1)) -> 46235 | G13: =IF(August2026Expenses[[#This Row],[Date]]="","",DAY(August2026Expenses[[#This Row],[Date]])) -> 4 | K13: Mortgage
A14: 46239 | B14: EWA Magnetic Phone Holder | C14: 407 | D14: Other | E14: Shopee | F14: =IF(August2026Expenses[[#This Row],[Date]]="","",DATE(YEAR(August2026Expenses[[#This Row],[Date]]),MONTH(August2026Expenses[[#This Row],[Date]]),1)) -> 46235 | G14: =IF(August2026Expenses[[#This Row],[Date]]="","",DAY(August2026Expenses[[#This Row],[Date]])) -> 5 | K14: Repairs
A15: 46240 | B15: Cheese Rolls | C15: 765 | D15: Housing | E15: Food | F15: =IF(August2026Expenses[[#This Row],[Date]]="","",DATE(YEAR(August2026Expenses[[#This Row],[Date]]),MONTH(August2026Expenses[[#This Row],[Date]]),1)) -> 46235 | G15: =IF(August2026Expenses[[#This Row],[Date]]="","",DAY(August2026Expenses[[#This Row],[Date]])) -> 6 | K15: Medicine
A16: 46240 | B16: Wonder Nature Cleaner | C16: 365 | D16: Other | E16: Shopee | F16: =IF(August2026Expenses[[#This Row],[Date]]="","",DATE(YEAR(August2026Expenses[[#This Row],[Date]]),MONTH(August2026Expenses[[#This Row],[Date]]),1)) -> 46235 | G16: =IF(August2026Expenses[[#This Row],[Date]]="","",DAY(August2026Expenses[[#This Row],[Date]])) -> 6 | K16: Doctor
A17: 46240 | B17: Shei Baon | C17: 1000 | D17: Personal | E17: Allowance | F17: =IF(August2026Expenses[[#This Row],[Date]]="","",DATE(YEAR(August2026Expenses[[#This Row],[Date]]),MONTH(August2026Expenses[[#This Row],[Date]]),1)) -> 46235 | G17: =IF(August2026Expenses[[#This Row],[Date]]="","",DAY(August2026Expenses[[#This Row],[Date]])) -> 6 | K17: Insurance
A18: 46240 | B18: Yuki's food and cat litter | C18: 1350 | D18: Housing | E18: Pet | F18: =IF(August2026Expenses[[#This Row],[Date]]="","",DATE(YEAR(August2026Expenses[[#This Row],[Date]]),MONTH(August2026Expenses[[#This Row],[Date]]),1)) -> 46235 | G18: =IF(August2026Expenses[[#This Row],[Date]]="","",DAY(August2026Expenses[[#This Row],[Date]])) -> 6 | K18: Movies
A19: 46240 | B19: Globe Load | C19: 150 | D19: Personal | E19: Subscriptions | F19: =IF(August2026Expenses[[#This Row],[Date]]="","",DATE(YEAR(August2026Expenses[[#This Row],[Date]]),MONTH(August2026Expenses[[#This Row],[Date]]),1)) -> 46235 | G19: =IF(August2026Expenses[[#This Row],[Date]]="","",DAY(August2026Expenses[[#This Row],[Date]])) -> 6 | K19: Subscriptions
A20: 46241 | B20: VIU | C20: 500 | D20: Entertainment | E20: Subscriptions | F20: =IF(August2026Expenses[[#This Row],[Date]]="","",DATE(YEAR(August2026Expenses[[#This Row],[Date]]),MONTH(August2026Expenses[[#This Row],[Date]]),1)) -> 46235 | G20: =IF(August2026Expenses[[#This Row],[Date]]="","",DAY(August2026Expenses[[#This Row],[Date]])) -> 7 | K20: Shopping
A21: 46242 | B21: Globe Load | C21: 120 | D21: Personal | E21: Subscriptions | F21: =IF(August2026Expenses[[#This Row],[Date]]="","",DATE(YEAR(August2026Expenses[[#This Row],[Date]]),MONTH(August2026Expenses[[#This Row],[Date]]),1)) -> 46235 | G21: =IF(August2026Expenses[[#This Row],[Date]]="","",DAY(August2026Expenses[[#This Row],[Date]])) -> 8 | K21: Clothing
A22: 46242 | B22: Wife hair color | C22: 1800 | D22: Personal | E22: Self-care | F22: =IF(August2026Expenses[[#This Row],[Date]]="","",DATE(YEAR(August2026Expenses[[#This Row],[Date]]),MONTH(August2026Expenses[[#This Row],[Date]]),1)) -> 46235 | G22: =IF(August2026Expenses[[#This Row],[Date]]="","",DAY(August2026Expenses[[#This Row],[Date]])) -> 8 | K22: Self-care
A23: 46243 | B23: Wife Allowance | C23: 1000 | D23: Personal | E23: Allowance | F23: =IF(August2026Expenses[[#This Row],[Date]]="","",DATE(YEAR(August2026Expenses[[#This Row],[Date]]),MONTH(August2026Expenses[[#This Row],[Date]]),1)) -> 46235 | G23: =IF(August2026Expenses[[#This Row],[Date]]="","",DAY(August2026Expenses[[#This Row],[Date]])) -> 9 | K23: Emergency Fund
... A25: 46243 | B25: Yapari Steak | C25: 1256 | D25: Personal | E25: Dining Out | F25: =IF(August2026Expenses[[#This Row],[Date]]="","",DATE(YEAR(August2026Expenses[[#This Row],[Date]]),MONTH(August2026Expenses[[#This Row],[Date]]),1)) -> 46235 | G25: =IF(August2026Expenses[[#This Row],[Date]]="","",DAY(August2026Expenses[[#This Row],[Date]])) -> 9 | K25: Food
A26: 46243 | B26: Grab Pasig City | C26: 1119 | D26: Grab | F26: =IF(August2026Expenses[[#This Row],[Date]]="","",DATE(YEAR(August2026Expenses[[#This Row],[Date]]),MONTH(August2026Expenses[[#This Row],[Date]]),1)) -> 46235 | G26: =IF(August2026Expenses[[#This Row],[Date]]="","",DAY(August2026Expenses[[#This Row],[Date]])) -> 9 | K26: Shopee
A27: 46243 | B27: Yabu | C27: 964 | D27: Food | E27: Dining Out | F27: =IF(August2026Expenses[[#This Row],[Date]]="","",DATE(YEAR(August2026Expenses[[#This Row],[Date]]),MONTH(August2026Expenses[[#This Row],[Date]]),1)) -> 46235 | G27: =IF(August2026Expenses[[#This Row],[Date]]="","",DAY(August2026Expenses[[#This Row],[Date]])) -> 9 | K27: Allowance
A28: 46243 | B28: Netflix | C28: 619 | D28: Entertainment | E28: Subscriptions | F28: =IF(August2026Expenses[[#This Row],[Date]]="","",DATE(YEAR(August2026Expenses[[#This Row],[Date]]),MONTH(August2026Expenses[[#This Row],[Date]]),1)) -> 46235 | G28: =IF(August2026Expenses[[#This Row],[Date]]="","",DAY(August2026Expenses[[#This Row],[Date]])) -> 9 | K28: Pet
A29: 46243 | B29: Caramia | C29: 148 | D29: Food | E29: Dining Out | F29: =IF(August2026Expenses[[#This Row],[Date]]="","",DATE(YEAR(August2026Expenses[[#This Row],[Date]]),MONTH(August2026Expenses[[#This Row],[Date]]),1)) -> 46235 | G29: =IF(August2026Expenses[[#This Row],[Date]]="","",DAY(August2026Expenses[[#This Row],[Date]])) -> 9
A30: 46243 | B30: SM Cinema Popcorn | C30: 335 | D30: Food | E30: Dining Out | F30: =IF(August2026Expenses[[#This Row],[Date]]="","",DATE(YEAR(August2026Expenses[[#This Row],[Date]]),MONTH(August2026Expenses[[#This Row],[Date]]),1)) -> 46235 | G30: =IF(August2026Expenses[[#This Row],[Date]]="","",DAY(August2026Expenses[[#This Row],[Date]])) -> 9
A31: 46243 | B31: Grab Pasig City | C31: 540 | D31: Grab | E31: Food | F31: =IF(August2026Expenses[[#This Row],[Date]]="","",DATE(YEAR(August2026Expenses[[#This Row],[Date]]),MONTH(August2026Expenses[[#This Row],[Date]]),1)) -> 46235 | G31: =IF(August2026Expenses[[#This Row],[Date]]="","",DAY(August2026Expenses[[#This Row],[Date]])) -> 9
A32: 46243 | B32: Google One | C32: 1111 | D32: Personal | E32: Subscriptions | F32: =IF(August2026Expenses[[#This Row],[Date]]="","",DATE(YEAR(August2026Expenses[[#This Row],[Date]]),MONTH(August2026Expenses[[#This Row],[Date]]),1)) -> 46235 | G32: =IF(August2026Expenses[[#This Row],[Date]]="","",DAY(August2026Expenses[[#This Row],[Date]])) -> 9
A33: 46243 | B33: Caltex Magallenes | C33: 1991 | D33: Transport | E33: Fuel | F33: =IF(August2026Expenses[[#This Row],[Date]]="","",DATE(YEAR(August2026Expenses[[#This Row],[Date]]),MONTH(August2026Expenses[[#This Row],[Date]]),1)) -> 46235 | G33: =IF(August2026Expenses[[#This Row],[Date]]="","",DAY(August2026Expenses[[#This Row],[Date]])) -> 9
A34: 46243 | B34: Jollibee | C34: 254 | D34: Food | E34: Food | F34: =IF(August2026Expenses[[#This Row],[Date]]="","",DATE(YEAR(August2026Expenses[[#This Row],[Date]]),MONTH(August2026Expenses[[#This Row],[Date]]),1)) -> 46235 | G34: =IF(August2026Expenses[[#This Row],[Date]]="","",DAY(August2026Expenses[[#This Row],[Date]])) -> 9
A35: 46243 | B35: Waifu Baon | C35: 1000 | D35: Personal | E35: Allowance | F35: =IF(August2026Expenses[[#This Row],[Date]]="","",DATE(YEAR(August2026Expenses[[#This Row],[Date]]),MONTH(August2026Expenses[[#This Row],[Date]]),1)) -> 46235 | G35: =IF(August2026Expenses[[#This Row],[Date]]="","",DAY(August2026Expenses[[#This Row],[Date]])) -> 9
A36: 46244 | C36: 1800 | F36: =IF(August2026Expenses[[#This Row],[Date]]="","",DATE(YEAR(August2026Expenses[[#This Row],[Date]]),MONTH(August2026Expenses[[#This Row],[Date]]),1)) -> 46235 | G36: =IF(August2026Expenses[[#This Row],[Date]]="","",DAY(August2026Expenses[[#This Row],[Date]])) -> 10
A37: 46246 | B37: Wife Allowance | C37: 1000 | D37: Personal | E37: Allowance | F37: =IF(August2026Expenses[[#This Row],[Date]]="","",DATE(YEAR(August2026Expenses[[#This Row],[Date]]),MONTH(August2026Expenses[[#This Row],[Date]]),1)) -> 46235 | G37: =IF(August2026Expenses[[#This Row],[Date]]="","",DAY(August2026Expenses[[#This Row],[Date]])) -> 12
A38: 46246 | B38: Weight Protein | C38: 2319 | D38: Personal | E38: Self-care | F38: =IF(August2026Expenses[[#This Row],[Date]]="","",DATE(YEAR(August2026Expenses[[#This Row],[Date]]),MONTH(August2026Expenses[[#This Row],[Date]]),1)) -> 46235 | G38: =IF(August2026Expenses[[#This Row],[Date]]="","",DAY(August2026Expenses[[#This Row],[Date]])) -> 12
A39: 46246 | B39: Alfamart Grace | C39: 407 | D39: Other | E39: Groceries | F39: =IF(August2026Expenses[[#This Row],[Date]]="","",DATE(YEAR(August2026Expenses[[#This Row],[Date]]),MONTH(August2026Expenses[[#This Row],[Date]]),1)) -> 46235 | G39: =IF(August2026Expenses[[#This Row],[Date]]="","",DAY(August2026Expenses[[#This Row],[Date]])) -> 12
A40: 46246 | B40: ATP | C40: 71 | D40: Other | E40: Groceries | F40: =IF(August2026Expenses[[#This Row],[Date]]="","",DATE(YEAR(August2026Expenses[[#This Row],[Date]]),MONTH(August2026Expenses[[#This Row],[Date]]),1)) -> 46235 | G40: =IF(August2026Expenses[[#This Row],[Date]]="","",DAY(August2026Expenses[[#This Row],[Date]])) -> 12
A106: Total entered | B106: =SUM(August2026Expenses[Amount]) -> 39635

Sheet Savings Dashboard
A1: Savings & Emergency Fund Dashboard
A2: Track savings balance, emergency fund target, remaining gap, and monthly progress.
A4: Emergency Goal | C4: Emergency Balance | E4: Progress | G4: Remaining | I4: Current Savings
A5: =B12 -> 575754 | C5: =SUMIFS(SavingsTable[Signed Amount],SavingsTable[Fund],"Emergency Fund") -> 144000 | E5: =IF(A5=0,0,C5/A5) -> 0.25010682 | G5: =MAX(A5-C5,0) -> 431754 | I5: =SUM(SavingsTable[Signed Amount]) -> 159730
A10: Monthly expense basis | B10: =Dashboard!C5 -> 95959
A11: Target months | B11: 6
A12: Goal formula | B12: =B10*B11 -> 575754
A14: MONTHLY SAVINGS SUMMARY | G14: BALANCE BY FUND
A15: Month | B15: Contributions | C15: Withdrawals | D15: Net Savings | E15: Running Balance | G15: Fund | H15: Balance | I15: % of Savings
A16: 46023 | B16: =SUMIFS(SavingsTable[Amount],SavingsTable[Transaction Type],"Contribution",SavingsTable[Month Start],A16) -> 0 | C16: =SUMIFS(SavingsTable[Amount],SavingsTable[Transaction Type],"Withdrawal",SavingsTable[Month Start],A16) -> 0 | D16: =B16-C16 -> 0 | E16: =SUM($D$16:D16) -> 0 | G16: Emergency Fund | H16: =SUMIFS(SavingsTable[Signed Amount],SavingsTable[Fund],G16) -> 144000 | I16: =IF($I$5=0,0,H16/$I$5) -> 0.90152132
A17: 46054 | B17: =SUMIFS(SavingsTable[Amount],SavingsTable[Transaction Type],"Contribution",SavingsTable[Month Start],A17) -> 0 | C17: =SUMIFS(SavingsTable[Amount],SavingsTable[Transaction Type],"Withdrawal",SavingsTable[Month Start],A17) -> 0 | D17: =B17-C17 -> 0 | E17: =SUM($D$16:D17) -> 0 | G17: General Savings | H17: =SUMIFS(SavingsTable[Signed Amount],SavingsTable[Fund],G17) -> 21800 | I17: =IF($I$5=0,0,H17/$I$5) -> 0.13648031
A18: 46082 | B18: =SUMIFS(SavingsTable[Amount],SavingsTable[Transaction Type],"Contribution",SavingsTable[Month Start],A18) -> 0 | C18: =SUMIFS(SavingsTable[Amount],SavingsTable[Transaction Type],"Withdrawal",SavingsTable[Month Start],A18) -> 0 | D18: =B18-C18 -> 0 | E18: =SUM($D$16:D18) -> 0 | G18: Travel Fund | H18: =SUMIFS(SavingsTable[Signed Amount],SavingsTable[Fund],G18) -> 0 | I18: =IF($I$5=0,0,H18/$I$5) -> 0
A19: 46113 | B19: =SUMIFS(SavingsTable[Amount],SavingsTable[Transaction Type],"Contribution",SavingsTable[Month Start],A19) -> 0 | C19: =SUMIFS(SavingsTable[Amount],SavingsTable[Transaction Type],"Withdrawal",SavingsTable[Month Start],A19) -> 0 | D19: =B19-C19 -> 0 | E19: =SUM($D$16:D19) -> 0 | G19: Investment Fund | H19: =SUMIFS(SavingsTable[Signed Amount],SavingsTable[Fund],G19) -> -6070 | I19: =IF($I$5=0,0,H19/$I$5) -> -0.038001628
A20: 46143 | B20: =SUMIFS(SavingsTable[Amount],SavingsTable[Transaction Type],"Contribution",SavingsTable[Month Start],A20) -> 0 | C20: =SUMIFS(SavingsTable[Amount],SavingsTable[Transaction Type],"Withdrawal",SavingsTable[Month Start],A20) -> 0 | D20: =B20-C20 -> 0 | E20: =SUM($D$16:D20) -> 0 | G20: Other | H20: =SUMIFS(SavingsTable[Signed Amount],SavingsTable[Fund],G20) -> 0 | I20: =IF($I$5=0,0,H20/$I$5) -> 0
A21: 46174 | B21: =SUMIFS(SavingsTable[Amount],SavingsTable[Transaction Type],"Contribution",SavingsTable[Month Start],A21) -> 0 | C21: =SUMIFS(SavingsTable[Amount],SavingsTable[Transaction Type],"Withdrawal",SavingsTable[Month Start],A21) -> 0 | D21: =B21-C21 -> 0 | E21: =SUM($D$16:D21) -> 0
A22: 46204 | B22: =SUMIFS(SavingsTable[Amount],SavingsTable[Transaction Type],"Contribution",SavingsTable[Month Start],A22) -> 0 | C22: =SUMIFS(SavingsTable[Amount],SavingsTable[Transaction Type],"Withdrawal",SavingsTable[Month Start],A22) -> 0 | D22: =B22-C22 -> 0 | E22: =SUM($D$16:D22) -> 0
A23: 46235 | B23: =SUMIFS(SavingsTable[Amount],SavingsTable[Transaction Type],"Contribution",SavingsTable[Month Start],A23) -> 203600 | C23: =SUMIFS(SavingsTable[Amount],SavingsTable[Transaction Type],"Withdrawal",SavingsTable[Month Start],A23) -> 43870 | D23: =B23-C23 -> 159730 | E23: =SUM($D$16:D23) -> 159730
A24: 46266 | B24: =SUMIFS(SavingsTable[Amount],SavingsTable[Transaction Type],"Contribution",SavingsTable[Month Start],A24) -> 0 | C24: =SUMIFS(SavingsTable[Amount],SavingsTable[Transaction Type],"Withdrawal",SavingsTable[Month Start],A24) -> 0 | D24: =B24-C24 -> 0 | E24: =SUM($D$16:D24) -> 159730
A25: 46296 | B25: =SUMIFS(SavingsTable[Amount],SavingsTable[Transaction Type],"Contribution",SavingsTable[Month Start],A25) -> 0 | C25: =SUMIFS(SavingsTable[Amount],SavingsTable[Transaction Type],"Withdrawal",SavingsTable[Month Start],A25) -> 0 | D25: =B25-C25 -> 0 | E25: =SUM($D$16:D25) -> 159730
A26: 46327 | B26: =SUMIFS(SavingsTable[Amount],SavingsTable[Transaction Type],"Contribution",SavingsTable[Month Start],A26) -> 0 | C26: =SUMIFS(SavingsTable[Amount],SavingsTable[Transaction Type],"Withdrawal",SavingsTable[Month Start],A26) -> 0 | D26: =B26-C26 -> 0 | E26: =SUM($D$16:D26) -> 159730
A27: 46357 | B27: =SUMIFS(SavingsTable[Amount],SavingsTable[Transaction Type],"Contribution",SavingsTable[Month Start],A27) -> 0 | C27: =SUMIFS(SavingsTable[Amount],SavingsTable[Transaction Type],"Withdrawal",SavingsTable[Month Start],A27) -> 0 | D27: =B27-C27 -> 0 | E27: =SUM($D$16:D27) -> 159730

Sheet Savings Tracker
A1: Savings & Emergency Fund Tracker | K1: Fund List | L1: Transaction Type List
A2: Record deposits as Contributions and any money taken out as Withdrawals. Dashboard totals update automatically. | K2: Emergency Fund | L2: Contribution
K3: General Savings | L3: Withdrawal
A4: Date | B4: Fund | C4: Transaction Type | D4: Amount | E4: Account | F4: Notes | G4: Month Start | H4: Signed Amount | K4: Travel Fund
A5: 46235 | B5: Emergency Fund | C5: Contribution | D5: 144000 | E5: BPI | F5: Savings | G5: =IF(SavingsTable[[#This Row],[Date]]="","",DATE(YEAR(SavingsTable[[#This Row],[Date]]),MONTH(SavingsTable[[#This Row],[Date]]),1)) -> 46235 | H5: =IF(SavingsTable[[#This Row],[Amount]]="","",IF(SavingsTable[[#This Row],[Transaction Type]]="Withdrawal",-SavingsTable[[#This Row],[Amount]],SavingsTable[[#This Row],[Amount]])) -> 144000 | K5: Investment Fund
A6: 46239 | B6: General Savings | C6: Withdrawal | D6: 20000 | E6: BPI | F6: BPI fund transfer to Mama BDO | G6: =IF(SavingsTable[[#This Row],[Date]]="","",DATE(YEAR(SavingsTable[[#This Row],[Date]]),MONTH(SavingsTable[[#This Row],[Date]]),1)) -> 46235 | H6: =IF(SavingsTable[[#This Row],[Amount]]="","",IF(SavingsTable[[#This Row],[Transaction Type]]="Withdrawal",-SavingsTable[[#This Row],[Amount]],SavingsTable[[#This Row],[Amount]])) -> -20000 | K6: Other
A7: 46240 | B7: General Savings | C7: Contribution | D7: 41600 | E7: BPI | F7: Part time salary | G7: =IF(SavingsTable[[#This Row],[Date]]="","",DATE(YEAR(SavingsTable[[#This Row],[Date]]),MONTH(SavingsTable[[#This Row],[Date]]),1)) -> 46235 | H7: =IF(SavingsTable[[#This Row],[Amount]]="","",IF(SavingsTable[[#This Row],[Transaction Type]]="Withdrawal",-SavingsTable[[#This Row],[Amount]],SavingsTable[[#This Row],[Amount]])) -> 41600
A8: 46240 | B8: Investment Fund | C8: Withdrawal | D8: 6070 | E8: BPI | F8: MEXC Initial Fund | G8: =IF(SavingsTable[[#This Row],[Date]]="","",DATE(YEAR(SavingsTable[[#This Row],[Date]]),MONTH(SavingsTable[[#This Row],[Date]]),1)) -> 46235 | H8: =IF(SavingsTable[[#This Row],[Amount]]="","",IF(SavingsTable[[#This Row],[Transaction Type]]="Withdrawal",-SavingsTable[[#This Row],[Amount]],SavingsTable[[#This Row],[Amount]])) -> -6070
A9: 46244 | B9: General Savings | C9: Withdrawal | D9: 14800 | E9: BPI | F9: Bills payment | G9: =IF(SavingsTable[[#This Row],[Date]]="","",DATE(YEAR(SavingsTable[[#This Row],[Date]]),MONTH(SavingsTable[[#This Row],[Date]]),1)) -> 46235 | H9: =IF(SavingsTable[[#This Row],[Amount]]="","",IF(SavingsTable[[#This Row],[Transaction Type]]="Withdrawal",-SavingsTable[[#This Row],[Amount]],SavingsTable[[#This Row],[Amount]])) -> -14800
A10: 46247 | B10: General Savings | C10: Contribution | D10: 8000 | E10: BPI | F10: Remaining Balance from Expenses | G10: =IF(SavingsTable[[#This Row],[Date]]="","",DATE(YEAR(SavingsTable[[#This Row],[Date]]),MONTH(SavingsTable[[#This Row],[Date]]),1)) -> 46235 | H10: =IF(SavingsTable[[#This Row],[Amount]]="","",IF(SavingsTable[[#This Row],[Transaction Type]]="Withdrawal",-SavingsTable[[#This Row],[Amount]],SavingsTable[[#This Row],[Amount]])) -> 8000
A11: 46247 | B11: General Savings | C11: Contribution | D11: 10000 | E11: BPI | F11: Repaid expense from savings | G11: =IF(SavingsTable[[#This Row],[Date]]="","",DATE(YEAR(SavingsTable[[#This Row],[Date]]),MONTH(SavingsTable[[#This Row],[Date]]),1)) -> 46235 | H11: =IF(SavingsTable[[#This Row],[Amount]]="","",IF(SavingsTable[[#This Row],[Transaction Type]]="Withdrawal",-SavingsTable[[#This Row],[Amount]],SavingsTable[[#This Row],[Amount]])) -> 10000
A12: 46256 | B12: General Savings | C12: Withdrawal | D12: 3000 | E12: BPI | F12: Calamansi allowance - MJ | G12: =IF(SavingsTable[[#This Row],[Date]]="","",DATE(YEAR(SavingsTable[[#This Row],[Date]]),MONTH(SavingsTable[[#This Row],[Date]]),1)) -> 46235 | H12: =IF(SavingsTable[[#This Row],[Amount]]="","",IF(SavingsTable[[#This Row],[Transaction Type]]="Withdrawal",-SavingsTable[[#This Row],[Amount]],SavingsTable[[#This Row],[Amount]])) -> -3000
G13: =IF(SavingsTable[[#This Row],[Date]]="","",DATE(YEAR(SavingsTable[[#This Row],[Date]]),MONTH(SavingsTable[[#This Row],[Date]]),1)) | H13: =IF(SavingsTable[[#This Row],[Amount]]="","",IF(SavingsTable[[#This Row],[Transaction Type]]="Withdrawal",-SavingsTable[[#This Row],[Amount]],SavingsTable[[#This Row],[Amount]]))
G14: =IF(SavingsTable[[#This Row],[Date]]="","",DATE(YEAR(SavingsTable[[#This Row],[Date]]),MONTH(SavingsTable[[#This Row],[Date]]),1)) | H14: =IF(SavingsTable[[#This Row],[Amount]]="","",IF(SavingsTable[[#This Row],[Transaction Type]]="Withdrawal",-SavingsTable[[#This Row],[Amount]],SavingsTable[[#This Row],[Amount]]))
G15: =IF(SavingsTable[[#This Row],[Date]]="","",DATE(YEAR(SavingsTable[[#This Row],[Date]]),MONTH(SavingsTable[[#This Row],[Date]]),1)) | H15: =IF(SavingsTable[[#This Row],[Amount]]="","",IF(SavingsTable[[#This Row],[Transaction Type]]="Withdrawal",-SavingsTable[[#This Row],[Amount]],SavingsTable[[#This Row],[Amount]]))
G16: =IF(SavingsTable[[#This Row],[Date]]="","",DATE(YEAR(SavingsTable[[#This Row],[Date]]),MONTH(SavingsTable[[#This Row],[Date]]),1)) | H16: =IF(SavingsTable[[#This Row],[Amount]]="","",IF(SavingsTable[[#This Row],[Transaction Type]]="Withdrawal",-SavingsTable[[#This Row],[Amount]],SavingsTable[[#This Row],[Amount]]))
G17: =IF(SavingsTable[[#This Row],[Date]]="","",DATE(YEAR(SavingsTable[[#This Row],[Date]]),MONTH(SavingsTable[[#This Row],[Date]]),1)) | H17: =IF(SavingsTable[[#This Row],[Amount]]="","",IF(SavingsTable[[#This Row],[Transaction Type]]="Withdrawal",-SavingsTable[[#This Row],[Amount]],SavingsTable[[#This Row],[Amount]]))
G18: =IF(SavingsTable[[#This Row],[Date]]="","",DATE(YEAR(SavingsTable[[#This Row],[Date]]),MONTH(SavingsTable[[#This Row],[Date]]),1)) | H18: =IF(SavingsTable[[#This Row],[Amount]]="","",IF(SavingsTable[[#This Row],[Transaction Type]]="Withdrawal",-SavingsTable[[#This Row],[Amount]],SavingsTable[[#This Row],[Amount]]))
G19: =IF(SavingsTable[[#This Row],[Date]]="","",DATE(YEAR(SavingsTable[[#This Row],[Date]]),MONTH(SavingsTable[[#This Row],[Date]]),1)) | H19: =IF(SavingsTable[[#This Row],[Amount]]="","",IF(SavingsTable[[#This Row],[Transaction Type]]="Withdrawal",-SavingsTable[[#This Row],[Amount]],SavingsTable[[#This Row],[Amount]]))
G20: =IF(SavingsTable[[#This Row],[Date]]="","",DATE(YEAR(SavingsTable[[#This Row],[Date]]),MONTH(SavingsTable[[#This Row],[Date]]),1)) | H20: =IF(SavingsTable[[#This Row],[Amount]]="","",IF(SavingsTable[[#This Row],[Transaction Type]]="Withdrawal",-SavingsTable[[#This Row],[Amount]],SavingsTable[[#This Row],[Amount]]))
G21: =IF(SavingsTable[[#This Row],[Date]]="","",DATE(YEAR(SavingsTable[[#This Row],[Date]]),MONTH(SavingsTable[[#This Row],[Date]]),1)) | H21: =IF(SavingsTable[[#This Row],[Amount]]="","",IF(SavingsTable[[#This Row],[Transaction Type]]="Withdrawal",-SavingsTable[[#This Row],[Amount]],SavingsTable[[#This Row],[Amount]]))
G22: =IF(SavingsTable[[#This Row],[Date]]="","",DATE(YEAR(SavingsTable[[#This Row],[Date]]),MONTH(SavingsTable[[#This Row],[Date]]),1)) | H22: =IF(SavingsTable[[#This Row],[Amount]]="","",IF(SavingsTable[[#This Row],[Transaction Type]]="Withdrawal",-SavingsTable[[#This Row],[Amount]],SavingsTable[[#This Row],[Amount]]))
G23: =IF(SavingsTable[[#This Row],[Date]]="","",DATE(YEAR(SavingsTable[[#This Row],[Date]]),MONTH(SavingsTable[[#This Row],[Date]]),1)) | H23: =IF(SavingsTable[[#This Row],[Amount]]="","",IF(SavingsTable[[#This Row],[Transaction Type]]="Withdrawal",-SavingsTable[[#This Row],[Amount]],SavingsTable[[#This Row],[Amount]]))
G24: =IF(SavingsTable[[#This Row],[Date]]="","",DATE(YEAR(SavingsTable[[#This Row],[Date]]),MONTH(SavingsTable[[#This Row],[Date]]),1)) | H24: =IF(SavingsTable[[#This Row],[Amount]]="","",IF(SavingsTable[[#This Row],[Transaction Type]]="Withdrawal",-SavingsTable[[#This Row],[Amount]],SavingsTable[[#This Row],[Amount]]))
... G104: =IF(SavingsTable[[#This Row],[Date]]="","",DATE(YEAR(SavingsTable[[#This Row],[Date]]),MONTH(SavingsTable[[#This Row],[Date]]),1)) | H104: =IF(SavingsTable[[#This Row],[Amount]]="","",IF(SavingsTable[[#This Row],[Transaction Type]]="Withdrawal",-SavingsTable[[#This Row],[Amount]],SavingsTable[[#This Row],[Amount]]))
A106: Current Balance | B106: =SUM(SavingsTable[Signed Amount]) -> 159730
A107: Total Contributions | B107: =SUMIFS(SavingsTable[Amount],SavingsTable[Transaction Type],"Contribution") -> 203600
A108: Total Withdrawals | B108: =SUMIFS(SavingsTable[Amount],SavingsTable[Transaction Type],"Withdrawal") -> 43870
A109: Emergency Fund Balance | B109: =SUMIFS(SavingsTable[Signed Amount],SavingsTable[Fund],"Emergency Fund") -> 144000

Sheet Web App Plan
A1: Web Application Blueprint
A2: Plan for converting this workbook into a personal finance web app with expenses, budgets, savings, dashboards, and charts.
A4: 1. Recommended Pages
A5: Page | B5: Purpose
A6: Login / Profile | B6: Secure access and user settings.
A7: Expense Entry | B7: Add/edit Date, Bills, Amount, Category, and Subcategory.
A8: Expense Dashboard | B8: Monthly spend, budget remaining, daily/category/subcategory charts.
A9: Savings Entry | B9: Add contributions and withdrawals by fund/account.
A10: Savings Dashboard | B10: Emergency goal, current savings, progress, fund balances, trend charts.
A11: Settings | B11: Manage category, subcategory, fund, and account lists.
A14: 2. Core Database Tables
A15: Table | B15: Key Fields
A16: users | B16: id, name, email, password_hash, created_at
A17: expenses | B17: id, user_id, date, bill_name, amount, category_id, subcategory_id
A18: categories | B18: id, user_id, name, type
A19: subcategories | B19: id, category_id, name
A20: savings_transactions | B20: id, user_id, date, fund_id, transaction_type, amount, account, notes
A21: funds | B21: id, user_id, name
A22: budgets | B22: id, user_id, month_start, monthly_budget, emergency_target_months
A25: 3. Workbook Formula Mapping
A26: Workbook Metric | B26: Web App Calculation
